2024-01-21 17:05:31,017 INFO    StreamThr :19144 [internal.py:wandb_internal():86] W&B internal server running at pid: 19144, started at: 2024-01-21 17:05:31.017377
2024-01-21 17:05:31,020 DEBUG   HandlerThread:19144 [handler.py:handle_request():146] handle_request: status
2024-01-21 17:05:31,031 INFO    WriterThread:19144 [datastore.py:open_for_write():87] open: F:\IIT_final_yr\Myproject\FypModel\pythonProject8\wandb\run-20240121_170530-m2vcign2\run-m2vcign2.wandb
2024-01-21 17:05:31,031 DEBUG   SenderThread:19144 [sender.py:send():382] send: header
2024-01-21 17:05:31,110 DEBUG   SenderThread:19144 [sender.py:send():382] send: run
2024-01-21 17:05:31,116 INFO    SenderThread:19144 [sender.py:_maybe_setup_resume():763] checking resume status for vvgl-ozu/vcnet-blind-image-inpainting/m2vcign2
2024-01-21 17:05:34,009 ERROR   SenderThread:19144 [internal_api.py:execute():373] 404 response executing GraphQL.
2024-01-21 17:05:34,009 ERROR   SenderThread:19144 [internal_api.py:execute():374] {"errors":[{"message":"project not found","path":["upsertBucket"]}],"data":{"upsertBucket":null}}
2024-01-21 17:05:34,010 ERROR   SenderThread:19144 [sender.py:send_run():987] It appears that you do not have permission to access the requested resource. Please reach out to the project owner to grant you access. If you have the correct permissions, verify that there are no issues with your networking setup.(Error 404: Not Found)
Traceback (most recent call last):
  File "C:\Users\sevitha\.conda\envs\pythonProject8\Lib\site-packages\wandb\sdk\lib\retry.py", line 131, in __call__
    result = self._call_fn(*args, **kwargs)
             ^^^^^^^^^^^^^^^^^^^^^^^^^^^^^^
  File "C:\Users\sevitha\.conda\envs\pythonProject8\Lib\site-packages\wandb\sdk\internal\internal_api.py", line 369, in execute
    return self.client.execute(*args, **kwargs)  # type: ignore
           ^^^^^^^^^^^^^^^^^^^^^^^^^^^^^^^^^^^^
  File "C:\Users\sevitha\.conda\envs\pythonProject8\Lib\site-packages\wandb\vendor\gql-0.2.0\wandb_gql\client.py", line 52, in execute
    result = self._get_result(document, *args, **kwargs)
             ^^^^^^^^^^^^^^^^^^^^^^^^^^^^^^^^^^^^^^^^^^^
  File "C:\Users\sevitha\.conda\envs\pythonProject8\Lib\site-packages\wandb\vendor\gql-0.2.0\wandb_gql\client.py", line 60, in _get_result
    return self.transport.execute(document, *args, **kwargs)
           ^^^^^^^^^^^^^^^^^^^^^^^^^^^^^^^^^^^^^^^^^^^^^^^^^
  File "C:\Users\sevitha\.conda\envs\pythonProject8\Lib\site-packages\wandb\sdk\lib\gql_request.py", line 59, in execute
    request.raise_for_status()
  File "C:\Users\sevitha\.conda\envs\pythonProject8\Lib\site-packages\requests\models.py", line 1021, in raise_for_status
    raise HTTPError(http_error_msg, response=self)
requests.exceptions.HTTPError: 404 Client Error: Not Found for url: https://api.wandb.ai/graphql

During handling of the above exception, another exception occurred:

Traceback (most recent call last):
  File "C:\Users\sevitha\.conda\envs\pythonProject8\Lib\site-packages\wandb\sdk\internal\sender.py", line 985, in send_run
    self._init_run(run, config_value_dict)
  File "C:\Users\sevitha\.conda\envs\pythonProject8\Lib\site-packages\wandb\sdk\internal\sender.py", line 1027, in _init_run
    server_run, inserted, server_messages = self._api.upsert_run(
                                            ^^^^^^^^^^^^^^^^^^^^^
  File "C:\Users\sevitha\.conda\envs\pythonProject8\Lib\site-packages\wandb\apis\normalize.py", line 73, in wrapper
    raise err
  File "C:\Users\sevitha\.conda\envs\pythonProject8\Lib\site-packages\wandb\apis\normalize.py", line 41, in wrapper
    return func(*args, **kwargs)
           ^^^^^^^^^^^^^^^^^^^^^
  File "C:\Users\sevitha\.conda\envs\pythonProject8\Lib\site-packages\wandb\sdk\internal\internal_api.py", line 2216, in upsert_run
    response = self.gql(
               ^^^^^^^^^
  File "C:\Users\sevitha\.conda\envs\pythonProject8\Lib\site-packages\wandb\sdk\internal\internal_api.py", line 341, in gql
    ret = self._retry_gql(
          ^^^^^^^^^^^^^^^^
  File "C:\Users\sevitha\.conda\envs\pythonProject8\Lib\site-packages\wandb\sdk\lib\retry.py", line 147, in __call__
    retry_timedelta_triggered = check_retry_fn(e)
                                ^^^^^^^^^^^^^^^^^
  File "C:\Users\sevitha\.conda\envs\pythonProject8\Lib\site-packages\wandb\util.py", line 965, in check_retry_fn
    return fallback_retry_fn(e)
           ^^^^^^^^^^^^^^^^^^^^
  File "C:\Users\sevitha\.conda\envs\pythonProject8\Lib\site-packages\wandb\util.py", line 907, in no_retry_auth
    raise CommError(
wandb.errors.CommError: It appears that you do not have permission to access the requested resource. Please reach out to the project owner to grant you access. If you have the correct permissions, verify that there are no issues with your networking setup.(Error 404: Not Found)
2024-01-21 17:05:35,953 DEBUG   HandlerThread:19144 [handler.py:handle_request():146] handle_request: shutdown
2024-01-21 17:05:35,953 INFO    HandlerThread:19144 [handler.py:finish():869] shutting down handler
2024-01-21 17:05:36,061 INFO    SenderThread:19144 [sender.py:finish():1572] shutting down sender
2024-01-21 17:05:36,153 INFO    WriterThread:19144 [datastore.py:close():296] close: F:\IIT_final_yr\Myproject\FypModel\pythonProject8\wandb\run-20240121_170530-m2vcign2\run-m2vcign2.wandb
